Workbook
Name n_nodes: Input_Data!#REF!
Name n_x: Input_Data!$F$7
Name n_y: Input_Data!$F$6

Sheet Input_Data
B2: 2D Boussinesq Model
B4: Time-Stepping | E4: Groundwater Model | H4: Setup Options
B5: Running Control | E5: Grid Discretization | H5: Name of the Simulation
B6: t0 | C6: 0 | D6: sec | E6: ny | F6: 60 | H6: Setup Name | I6: PERTH_CALIBRATION_400_particles_60min
B7: tfinal | C7: =MAX(Inflow_BC!B4:B1048576)*60 -> 2329200 | D7: sec | E7: nx | F7: 24
B8: tsave | C8: 3600 | D8: sec | E8: Width | F8: 11.5 | G8: m
B9: dtUZ | C9: 3600 | D9: sec | E9: Length | F9: 30 | G9: m
B10: dtGW | C10: 1800 | D10: sec | E10: H | F10: 1 | G10: m
B11: AdaptiveUZ | C11: 1 | E11: UZ Surrogate Model
B12: AdaptiveGW | C12: 1 | E12: n | F12: 1.76
B13: flag_PF | C13: 1 | E13: porosity | F13: 0.385
E14: alpha | F14: -2.33 | G14: 1/m
E15: k | F15: =5*10^(-5) -> 5e-05 | G15: 1/sec
E16: S0UZ0 | F16: 10 | G16: mm
E17: df | F17: 0.9

Sheet Boundary_Conditions
B2: Boundary Conditions | D2: 0
B3: Instructions: | C3: Enter the index of each boundary condition. The indexes entered in this matrix are associated with the B.C entered in the input data
B4: Boundary Conditions at the Perimeter
B5: Dirichlet Index | C5: Dirichlet Value [head in m] | D5: Neumann B.C | E5: Neumann B.C [flux in m/s] | H5: x[cells]
B6: 1 | C6: 3.7328138 | D6: 25 | E6: 0 | G6: y [cells] | H6: 25 | I6: 25 | J6: 25 | K6: 25 | L6: 25 | M6: 25 | N6: 25 | O6: 25 | P6: 25 | Q6: 25 | R6: 25 | S6: 25 | T6: 25 | U6: 25 | V6: 25 | W6: 25 | X6: 25 | Y6: 25 | Z6: 25 | AA6: 25 | AB6: 25 | AC6: 25 | AD6: 25 | AE6: 25
B7: 2 | C7: 3.6926079 | H7: 25 | I7: 0 | J7: 0 | K7: 0 | L7: 0 | M7: 0 | N7: 0 | O7: 0 | P7: 0 | Q7: 0 | R7: 0 | S7: 0 | T7: 0 | U7: 0 | V7: 0 | W7: 0 | X7: 0 | Y7: 0 | Z7: 0 | AA7: 0 | AB7: 0 | AC7: 0 | AD7: 0 | AE7: 25
B8: 3 | C8: 3.6526809 | H8: 25 | I8: 0 | J8: 0 | K8: 0 | L8: 0 | M8: 0 | N8: 0 | O8: 0 | P8: 0 | Q8: 0 | R8: 0 | S8: 0 | T8: 0 | U8: 0 | V8: 0 | W8: 0 | X8: 0 | Y8: 0 | Z8: 0 | AA8: 0 | AB8: 0 | AC8: 0 | AD8: 0 | AE8: 25
B9: 4 | C9: 3.6127982 | H9: 25 | I9: 0 | J9: 0 | K9: 0 | L9: 0 | M9: 0 | N9: 0 | O9: 0 | P9: 0 | Q9: 0 | R9: 0 | S9: 0 | T9: 0 | U9: 0 | V9: 0 | W9: 0 | X9: 0 | Y9: 0 | Z9: 0 | AA9: 0 | AB9: 0 | AC9: 0 | AD9: 0 | AE9: 25
B10: 5 | C10: 3.5754051 | H10: 25 | I10: 0 | J10: 0 | K10: 0 | L10: 0 | M10: 0 | N10: 0 | O10: 0 | P10: 0 | Q10: 0 | R10: 0 | S10: 0 | T10: 0 | U10: 0 | V10: 0 | W10: 0 | X10: 0 | Y10: 0 | Z10: 0 | AA10: 0 | AB10: 0 | AC10: 0 | AD10: 0 | AE10: 25
B11: 6 | C11: 3.5352635 | H11: 25 | I11: 0 | J11: 0 | K11: 0 | L11: 0 | M11: 0 | N11: 0 | O11: 0 | P11: 0 | Q11: 0 | R11: 0 | S11: 0 | T11: 0 | U11: 0 | V11: 0 | W11: 0 | X11: 0 | Y11: 0 | Z11: 0 | AA11: 0 | AB11: 0 | AC11: 0 | AD11: 0 | AE11: 25
B12: 7 | C12: 3.4676585 | H12: 25 | I12: 0 | J12: 0 | K12: 0 | L12: 0 | M12: 0 | N12: 0 | O12: 0 | P12: 0 | Q12: 0 | R12: 0 | S12: 0 | T12: 0 | U12: 0 | V12: 0 | W12: 0 | X12: 0 | Y12: 0 | Z12: 0 | AA12: 0 | AB12: 0 | AC12: 0 | AD12: 0 | AE12: 25
B13: 8 | C13: 3.3674531 | H13: 25 | I13: 0 | J13: 0 | K13: 0 | L13: 0 | M13: 0 | N13: 0 | O13: 0 | P13: 0 | Q13: 0 | R13: 0 | S13: 0 | T13: 0 | U13: 0 | V13: 0 | W13: 0 | X13: 0 | Y13: 0 | Z13: 0 | AA13: 0 | AB13: 0 | AC13: 0 | AD13: 0 | AE13: 25
B14: 9 | C14: 3.2571411 | H14: 25 | I14: 0 | J14: 0 | K14: 0 | L14: 0 | M14: 0 | N14: 0 | O14: 0 | P14: 0 | Q14: 0 | R14: 0 | S14: 0 | T14: 0 | U14: 0 | V14: 0 | W14: 0 | X14: 0 | Y14: 0 | Z14: 0 | AA14: 0 | AB14: 0 | AC14: 0 | AD14: 0 | AE14: 25
B15: 10 | C15: 3.1502023 | H15: 25 | I15: 0 | J15: 0 | K15: 0 | L15: 0 | M15: 0 | N15: 0 | O15: 0 | P15: 0 | Q15: 0 | R15: 0 | S15: 0 | T15: 0 | U15: 0 | V15: 0 | W15: 0 | X15: 0 | Y15: 0 | Z15: 0 | AA15: 0 | AB15: 0 | AC15: 0 | AD15: 0 | AE15: 25
B16: 11 | C16: 3.0642624 | H16: 25 | I16: 0 | J16: 0 | K16: 0 | L16: 0 | M16: 0 | N16: 0 | O16: 0 | P16: 0 | Q16: 0 | R16: 0 | S16: 0 | T16: 0 | U16: 0 | V16: 0 | W16: 0 | X16: 0 | Y16: 0 | Z16: 0 | AA16: 0 | AB16: 0 | AC16: 0 | AD16: 0 | AE16: 25
B17: 12 | C17: 3.0149402 | H17: 25 | I17: 0 | J17: 0 | K17: 0 | L17: 0 | M17: 0 | N17: 0 | O17: 0 | P17: 0 | Q17: 0 | R17: 0 | S17: 0 | T17: 0 | U17: 0 | V17: 0 | W17: 0 | X17: 0 | Y17: 0 | Z17: 0 | AA17: 0 | AB17: 0 | AC17: 0 | AD17: 0 | AE17: 25
B18: 13 | C18: 3.0282245 | H18: 25 | I18: 0 | J18: 0 | K18: 0 | L18: 0 | M18: 0 | N18: 0 | O18: 0 | P18: 0 | Q18: 0 | R18: 0 | S18: 0 | T18: 0 | U18: 0 | V18: 0 | W18: 0 | X18: 0 | Y18: 0 | Z18: 0 | AA18: 0 | AB18: 0 | AC18: 0 | AD18: 0 | AE18: 25
... B29: 24 | C29: 3.7512712 | H29: 25 | I29: 0 | J29: 0 | K29: 0 | L29: 0 | M29: 0 | N29: 0 | O29: 0 | P29: 0 | Q29: 0 | R29: 0 | S29: 0 | T29: 0 | U29: 0 | V29: 0 | W29: 0 | X29: 0 | Y29: 0 | Z29: 0 | AA29: 0 | AB29: 0 | AC29: 0 | AD29: 0 | AE29: 25
H30: 25 | I30: 0 | J30: 0 | K30: 0 | L30: 0 | M30: 0 | N30: 0 | O30: 0 | P30: 0 | Q30: 0 | R30: 0 | S30: 0 | T30: 0 | U30: 0 | V30: 0 | W30: 0 | X30: 0 | Y30: 0 | Z30: 0 | AA30: 0 | AB30: 0 | AC30: 0 | AD30: 0 | AE30: 25
H31: 25 | I31: 0 | J31: 0 | K31: 0 | L31: 0 | M31: 0 | N31: 0 | O31: 0 | P31: 0 | Q31: 0 | R31: 0 | S31: 0 | T31: 0 | U31: 0 | V31: 0 | W31: 0 | X31: 0 | Y31: 0 | Z31: 0 | AA31: 0 | AB31: 0 | AC31: 0 | AD31: 0 | AE31: 25
H32: 25 | I32: 0 | J32: 0 | K32: 0 | L32: 0 | M32: 0 | N32: 0 | O32: 0 | P32: 0 | Q32: 0 | R32: 0 | S32: 0 | T32: 0 | U32: 0 | V32: 0 | W32: 0 | X32: 0 | Y32: 0 | Z32: 0 | AA32: 0 | AB32: 0 | AC32: 0 | AD32: 0 | AE32: 25
H33: 25 | I33: 0 | J33: 0 | K33: 0 | L33: 0 | M33: 0 | N33: 0 | O33: 0 | P33: 0 | Q33: 0 | R33: 0 | S33: 0 | T33: 0 | U33: 0 | V33: 0 | W33: 0 | X33: 0 | Y33: 0 | Z33: 0 | AA33: 0 | AB33: 0 | AC33: 0 | AD33: 0 | AE33: 25
H34: 25 | I34: 0 | J34: 0 | K34: 0 | L34: 0 | M34: 0 | N34: 0 | O34: 0 | P34: 0 | Q34: 0 | R34: 0 | S34: 0 | T34: 0 | U34: 0 | V34: 0 | W34: 0 | X34: 0 | Y34: 0 | Z34: 0 | AA34: 0 | AB34: 0 | AC34: 0 | AD34: 0 | AE34: 25
H35: 25 | I35: 0 | J35: 0 | K35: 0 | L35: 0 | M35: 0 | N35: 0 | O35: 0 | P35: 0 | Q35: 0 | R35: 0 | S35: 0 | T35: 0 | U35: 0 | V35: 0 | W35: 0 | X35: 0 | Y35: 0 | Z35: 0 | AA35: 0 | AB35: 0 | AC35: 0 | AD35: 0 | AE35: 25
H36: 25 | I36: 0 | J36: 0 | K36: 0 | L36: 0 | M36: 0 | N36: 0 | O36: 0 | P36: 0 | Q36: 0 | R36: 0 | S36: 0 | T36: 0 | U36: 0 | V36: 0 | W36: 0 | X36: 0 | Y36: 0 | Z36: 0 | AA36: 0 | AB36: 0 | AC36: 0 | AD36: 0 | AE36: 25
H37: 25 | I37: 0 | J37: 0 | K37: 0 | L37: 0 | M37: 0 | N37: 0 | O37: 0 | P37: 0 | Q37: 0 | R37: 0 | S37: 0 | T37: 0 | U37: 0 | V37: 0 | W37: 0 | X37: 0 | Y37: 0 | Z37: 0 | AA37: 0 | AB37: 0 | AC37: 0 | AD37: 0 | AE37: 25
H38: 25 | I38: 0 | J38: 0 | K38: 0 | L38: 0 | M38: 0 | N38: 0 | O38: 0 | P38: 0 | Q38: 0 | R38: 0 | S38: 0 | T38: 0 | U38: 0 | V38: 0 | W38: 0 | X38: 0 | Y38: 0 | Z38: 0 | AA38: 0 | AB38: 0 | AC38: 0 | AD38: 0 | AE38: 25
H39: 25 | I39: 0 | J39: 0 | K39: 0 | L39: 0 | M39: 0 | N39: 0 | O39: 0 | P39: 0 | Q39: 0 | R39: 0 | S39: 0 | T39: 0 | U39: 0 | V39: 0 | W39: 0 | X39: 0 | Y39: 0 | Z39: 0 | AA39: 0 | AB39: 0 | AC39: 0 | AD39: 0 | AE39: 25
H40: 25 | I40: 0 | J40: 0 | K40: 0 | L40: 0 | M40: 0 | N40: 0 | O40: 0 | P40: 0 | Q40: 0 | R40: 0 | S40: 0 | T40: 0 | U40: 0 | V40: 0 | W40: 0 | X40: 0 | Y40: 0 | Z40: 0 | AA40: 0 | AB40: 0 | AC40: 0 | AD40: 0 | AE40: 25
H41: 25 | I41: 0 | J41: 0 | K41: 0 | L41: 0 | M41: 0 | N41: 0 | O41: 0 | P41: 0 | Q41: 0 | R41: 0 | S41: 0 | T41: 0 | U41: 0 | V41: 0 | W41: 0 | X41: 0 | Y41: 0 | Z41: 0 | AA41: 0 | AB41: 0 | AC41: 0 | AD41: 0 | AE41: 25
... H65: 1 | I65: 2 | J65: 3 | K65: 4 | L65: 5 | M65: 6 | N65: 7 | O65: 8 | P65: 9 | Q65: 10 | R65: 11 | S65: 12 | T65: 13 | U65: 14 | V65: 15 | W65: 16 | X65: 17 | Y65: 18 | Z65: 19 | AA65: 20 | AB65: 21 | AC65: 22 | AD65: 23 | AE65: 24

Sheet GW_S
B2: Specific Yield [-]
B3: Instructions: | C3: Paste the initial Specific Yield data [-] where y is the vertical axis and x is the horizontal axis
C4: x[cells]
B5: y [cells] | C5: =$B$6 -> 0.3 | D5: =$B$6 -> 0.3 | E5: =$B$6 -> 0.3 | F5: =$B$6 -> 0.3 | G5: =$B$6 -> 0.3 | H5: =$B$6 -> 0.3 | I5: =$B$6 -> 0.3 | J5: =$B$6 -> 0.3 | ... Z5: =$B$6 -> 0.3
B6: 0.3 | C6: =$B$6 -> 0.3 | D6: =$B$6 -> 0.3 | E6: =$B$6 -> 0.3 | F6: =$B$6 -> 0.3 | G6: =$B$6 -> 0.3 | H6: =$B$6 -> 0.3 | I6: =$B$6 -> 0.3 | J6: =$B$6 -> 0.3 | ... Z6: =$B$6 -> 0.3
C7: =$B$6 -> 0.3 | D7: =$B$6 -> 0.3 | E7: =$B$6 -> 0.3 | F7: =$B$6 -> 0.3 | G7: =$B$6 -> 0.3 | H7: =$B$6 -> 0.3 | I7: =$B$6 -> 0.3 | J7: =$B$6 -> 0.3 | ... Z7: =$B$6 -> 0.3
C8: =$B$6 -> 0.3 | D8: =$B$6 -> 0.3 | E8: =$B$6 -> 0.3 | F8: =$B$6 -> 0.3 | G8: =$B$6 -> 0.3 | H8: =$B$6 -> 0.3 | I8: =$B$6 -> 0.3 | J8: =$B$6 -> 0.3 | ... Z8: =$B$6 -> 0.3
C9: =$B$6 -> 0.3 | D9: =$B$6 -> 0.3 | E9: =$B$6 -> 0.3 | F9: =$B$6 -> 0.3 | G9: =$B$6 -> 0.3 | H9: =$B$6 -> 0.3 | I9: =$B$6 -> 0.3 | J9: =$B$6 -> 0.3 | ... Z9: =$B$6 -> 0.3
C10: =$B$6 -> 0.3 | D10: =$B$6 -> 0.3 | E10: =$B$6 -> 0.3 | F10: =$B$6 -> 0.3 | G10: =$B$6 -> 0.3 | H10: =$B$6 -> 0.3 | I10: =$B$6 -> 0.3 | J10: =$B$6 -> 0.3 | ... Z10: =$B$6 -> 0.3
C11: =$B$6 -> 0.3 | D11: =$B$6 -> 0.3 | E11: =$B$6 -> 0.3 | F11: =$B$6 -> 0.3 | G11: =$B$6 -> 0.3 | H11: =$B$6 -> 0.3 | I11: =$B$6 -> 0.3 | J11: =$B$6 -> 0.3 | ... Z11: =$B$6 -> 0.3
C12: =$B$6 -> 0.3 | D12: =$B$6 -> 0.3 | E12: =$B$6 -> 0.3 | F12: =$B$6 -> 0.3 | G12: =$B$6 -> 0.3 | H12: =$B$6 -> 0.3 | I12: =$B$6 -> 0.3 | J12: =$B$6 -> 0.3 | ... Z12: =$B$6 -> 0.3
C13: =$B$6 -> 0.3 | D13: =$B$6 -> 0.3 | E13: =$B$6 -> 0.3 | F13: =$B$6 -> 0.3 | G13: =$B$6 -> 0.3 | H13: =$B$6 -> 0.3 | I13: =$B$6 -> 0.3 | J13: =$B$6 -> 0.3 | ... Z13: =$B$6 -> 0.3
C14: =$B$6 -> 0.3 | D14: =$B$6 -> 0.3 | E14: =$B$6 -> 0.3 | F14: =$B$6 -> 0.3 | G14: =$B$6 -> 0.3 | H14: =$B$6 -> 0.3 | I14: =$B$6 -> 0.3 | J14: =$B$6 -> 0.3 | ... Z14: =$B$6 -> 0.3
C15: =$B$6 -> 0.3 | D15: =$B$6 -> 0.3 | E15: =$B$6 -> 0.3 | F15: =$B$6 -> 0.3 | G15: =$B$6 -> 0.3 | H15: =$B$6 -> 0.3 | I15: =$B$6 -> 0.3 | J15: =$B$6 -> 0.3 | ... Z15: =$B$6 -> 0.3
C16: =$B$6 -> 0.3 | D16: =$B$6 -> 0.3 | E16: =$B$6 -> 0.3 | F16: =$B$6 -> 0.3 | G16: =$B$6 -> 0.3 | H16: =$B$6 -> 0.3 | I16: =$B$6 -> 0.3 | J16: =$B$6 -> 0.3 | ... Z16: =$B$6 -> 0.3
C17: =$B$6 -> 0.3 | D17: =$B$6 -> 0.3 | E17: =$B$6 -> 0.3 | F17: =$B$6 -> 0.3 | G17: =$B$6 -> 0.3 | H17: =$B$6 -> 0.3 | I17: =$B$6 -> 0.3 | J17: =$B$6 -> 0.3 | ... Z17: =$B$6 -> 0.3
C18: =$B$6 -> 0.3 | D18: =$B$6 -> 0.3 | E18: =$B$6 -> 0.3 | F18: =$B$6 -> 0.3 | G18: =$B$6 -> 0.3 | H18: =$B$6 -> 0.3 | I18: =$B$6 -> 0.3 | J18: =$B$6 -> 0.3 | ... Z18: =$B$6 -> 0.3
... C64: =$B$6 -> 0.3 | D64: =$B$6 -> 0.3 | E64: =$B$6 -> 0.3 | F64: =$B$6 -> 0.3 | G64: =$B$6 -> 0.3 | H64: =$B$6 -> 0.3 | I64: =$B$6 -> 0.3 | J64: =$B$6 -> 0.3 | ... Z64: =$B$6 -> 0.3

Sheet GW_Depth
B2: Initial GW Depth [m]
B3: Instructions: | C3: Paste the initial GW table data [m] where y is the vertical axis and x is the horizontal axis
C4: x[cells]
B5: y [cells] | C5: 0.05 | D5: 0.05 | E5: 0.05 | F5: 0.05 | G5: 0.05 | H5: 0.05 | I5: 0.05 | J5: 0.05 | K5: 0.05 | L5: 0.05 | M5: 0.05 | N5: 0.05 | O5: 0.05 | P5: 0.05 | Q5: 0.05 | R5: 0.05 | S5: 0.05 | T5: 0.05 | U5: 0.05 | V5: 0.05 | W5: 0.05 | X5: 0.05 | Y5: 0.05 | Z5: 0.05
C6: 0.05 | D6: 0.05 | E6: 0.05 | F6: 0.05 | G6: 0.05 | H6: 0.05 | I6: 0.05 | J6: 0.05 | K6: 0.05 | L6: 0.05 | M6: 0.05 | N6: 0.05 | O6: 0.05 | P6: 0.05 | Q6: 0.05 | R6: 0.05 | S6: 0.05 | T6: 0.05 | U6: 0.05 | V6: 0.05 | W6: 0.05 | X6: 0.05 | Y6: 0.05 | Z6: 0.05
C7: 0.05 | D7: 0.05 | E7: 0.05 | F7: 0.05 | G7: 0.05 | H7: 0.05 | I7: 0.05 | J7: 0.05 | K7: 0.05 | L7: 0.05 | M7: 0.05 | N7: 0.05 | O7: 0.05 | P7: 0.05 | Q7: 0.05 | R7: 0.05 | S7: 0.05 | T7: 0.05 | U7: 0.05 | V7: 0.05 | W7: 0.05 | X7: 0.05 | Y7: 0.05 | Z7: 0.05
C8: 0.05 | D8: 0.05 | E8: 0.05 | F8: 0.05 | G8: 0.05 | H8: 0.05 | I8: 0.05 | J8: 0.05 | K8: 0.05 | L8: 0.05 | M8: 0.05 | N8: 0.05 | O8: 0.05 | P8: 0.05 | Q8: 0.05 | R8: 0.05 | S8: 0.05 | T8: 0.05 | U8: 0.05 | V8: 0.05 | W8: 0.05 | X8: 0.05 | Y8: 0.05 | Z8: 0.05
C9: 0.05 | D9: 0.05 | E9: 0.05 | F9: 0.05 | G9: 0.05 | H9: 0.05 | I9: 0.05 | J9: 0.05 | K9: 0.05 | L9: 0.05 | M9: 0.05 | N9: 0.05 | O9: 0.05 | P9: 0.05 | Q9: 0.05 | R9: 0.05 | S9: 0.05 | T9: 0.05 | U9: 0.05 | V9: 0.05 | W9: 0.05 | X9: 0.05 | Y9: 0.05 | Z9: 0.05
C10: 0.05 | D10: 0.05 | E10: 0.05 | F10: 0.05 | G10: 0.05 | H10: 0.05 | I10: 0.05 | J10: 0.05 | K10: 0.05 | L10: 0.05 | M10: 0.05 | N10: 0.05 | O10: 0.05 | P10: 0.05 | Q10: 0.05 | R10: 0.05 | S10: 0.05 | T10: 0.05 | U10: 0.05 | V10: 0.05 | W10: 0.05 | X10: 0.05 | Y10: 0.05 | Z10: 0.05
C11: 0.05 | D11: 0.05 | E11: 0.05 | F11: 0.05 | G11: 0.05 | H11: 0.05 | I11: 0.05 | J11: 0.05 | K11: 0.05 | L11: 0.05 | M11: 0.05 | N11: 0.05 | O11: 0.05 | P11: 0.05 | Q11: 0.05 | R11: 0.05 | S11: 0.05 | T11: 0.05 | U11: 0.05 | V11: 0.05 | W11: 0.05 | X11: 0.05 | Y11: 0.05 | Z11: 0.05
C12: 0.05 | D12: 0.05 | E12: 0.05 | F12: 0.05 | G12: 0.05 | H12: 0.05 | I12: 0.05 | J12: 0.05 | K12: 0.05 | L12: 0.05 | M12: 0.05 | N12: 0.05 | O12: 0.05 | P12: 0.05 | Q12: 0.05 | R12: 0.05 | S12: 0.05 | T12: 0.05 | U12: 0.05 | V12: 0.05 | W12: 0.05 | X12: 0.05 | Y12: 0.05 | Z12: 0.05
C13: 0.05 | D13: 0.05 | E13: 0.05 | F13: 0.05 | G13: 0.05 | H13: 0.05 | I13: 0.05 | J13: 0.05 | K13: 0.05 | L13: 0.05 | M13: 0.05 | N13: 0.05 | O13: 0.05 | P13: 0.05 | Q13: 0.05 | R13: 0.05 | S13: 0.05 | T13: 0.05 | U13: 0.05 | V13: 0.05 | W13: 0.05 | X13: 0.05 | Y13: 0.05 | Z13: 0.05
C14: 0.05 | D14: 0.05 | E14: 0.05 | F14: 0.05 | G14: 0.05 | H14: 0.05 | I14: 0.05 | J14: 0.05 | K14: 0.05 | L14: 0.05 | M14: 0.05 | N14: 0.05 | O14: 0.05 | P14: 0.05 | Q14: 0.05 | R14: 0.05 | S14: 0.05 | T14: 0.05 | U14: 0.05 | V14: 0.05 | W14: 0.05 | X14: 0.05 | Y14: 0.05 | Z14: 0.05
C15: 0.05 | D15: 0.05 | E15: 0.05 | F15: 0.05 | G15: 0.05 | H15: 0.05 | I15: 0.05 | J15: 0.05 | K15: 0.05 | L15: 0.05 | M15: 0.05 | N15: 0.05 | O15: 0.05 | P15: 0.05 | Q15: 0.05 | R15: 0.05 | S15: 0.05 | T15: 0.05 | U15: 0.05 | V15: 0.05 | W15: 0.05 | X15: 0.05 | Y15: 0.05 | Z15: 0.05
C16: 0.05 | D16: 0.05 | E16: 0.05 | F16: 0.05 | G16: 0.05 | H16: 0.05 | I16: 0.05 | J16: 0.05 | K16: 0.05 | L16: 0.05 | M16: 0.05 | N16: 0.05 | O16: 0.05 | P16: 0.05 | Q16: 0.05 | R16: 0.05 | S16: 0.05 | T16: 0.05 | U16: 0.05 | V16: 0.05 | W16: 0.05 | X16: 0.05 | Y16: 0.05 | Z16: 0.05
C17: 0.05 | D17: 0.05 | E17: 0.05 | F17: 0.05 | G17: 0.05 | H17: 0.05 | I17: 0.05 | J17: 0.05 | K17: 0.05 | L17: 0.05 | M17: 0.05 | N17: 0.05 | O17: 0.05 | P17: 0.05 | Q17: 0.05 | R17: 0.05 | S17: 0.05 | T17: 0.05 | U17: 0.05 | V17: 0.05 | W17: 0.05 | X17: 0.05 | Y17: 0.05 | Z17: 0.05
... C64: 0 | D64: 0 | E64: 0 | F64: 0 | G64: 0 | H64: 0 | I64: 0 | J64: 0 | K64: 0 | L64: 0 | M64: 0 | N64: 0 | O64: 0 | P64: 0 | Q64: 0 | R64: 0 | S64: 0 | T64: 0 | U64: 0 | V64: 0 | W64: 0 | X64: 0 | Y64: 0 | Z64: 0

Sheet GW_Ksat
B2: GW Ksat [m/s]
B3: Instructions: | C3: Paste the initial GW saturated hydraulic conductivity data [m/s] where y is the vertical axis and x is the horizontal axis
C4: x[cells]
B5: y [cells] | C5: =$B$9 -> 7.9433e-05 | D5: =$B$9 -> 7.9433e-05 | E5: =$B$9 -> 7.9433e-05 | F5: =$B$9 -> 7.9433e-05 | G5: =$B$9 -> 7.9433e-05 | H5: =$B$9 -> 7.9433e-05 | I5: =$B$9 -> 7.9433e-05 | J5: =$B$9 -> 7.9433e-05 | ... Z5: =$B$9 -> 7.9433e-05
B6: =7.9433*10^(-5) -> 7.9433e-05 | C6: =$B$9 -> 7.9433e-05 | D6: =$B$9 -> 7.9433e-05 | E6: =$B$9 -> 7.9433e-05 | F6: =$B$9 -> 7.9433e-05 | G6: =$B$9 -> 7.9433e-05 | H6: =$B$9 -> 7.9433e-05 | I6: =$B$9 -> 7.9433e-05 | J6: =$B$9 -> 7.9433e-05 | ... Z6: =$B$9 -> 7.9433e-05
B7: factor | C7: =$B$9 -> 7.9433e-05 | D7: =$B$9 -> 7.9433e-05 | E7: =$B$9 -> 7.9433e-05 | F7: =$B$9 -> 7.9433e-05 | G7: =$B$9 -> 7.9433e-05 | H7: =$B$9 -> 7.9433e-05 | I7: =$B$9 -> 7.9433e-05 | J7: =$B$9 -> 7.9433e-05 | ... Z7: =$B$9 -> 7.9433e-05
B8: 1 | C8: =$B$9 -> 7.9433e-05 | D8: =$B$9 -> 7.9433e-05 | E8: =$B$9 -> 7.9433e-05 | F8: =$B$9 -> 7.9433e-05 | G8: =$B$9 -> 7.9433e-05 | H8: =$B$9 -> 7.9433e-05 | I8: =$B$9 -> 7.9433e-05 | J8: =$B$9 -> 7.9433e-05 | ... Z8: =$B$9 -> 7.9433e-05
B9: =B6*B8 -> 7.9433e-05 | C9: =$B$9 -> 7.9433e-05 | D9: =$B$9 -> 7.9433e-05 | E9: =$B$9 -> 7.9433e-05 | F9: =$B$9 -> 7.9433e-05 | G9: =$B$9 -> 7.9433e-05 | H9: =$B$9 -> 7.9433e-05 | I9: =$B$9 -> 7.9433e-05 | J9: =$B$9 -> 7.9433e-05 | ... Z9: =$B$9 -> 7.9433e-05
C10: =$B$9 -> 7.9433e-05 | D10: =$B$9 -> 7.9433e-05 | E10: =$B$9 -> 7.9433e-05 | F10: =$B$9 -> 7.9433e-05 | G10: =$B$9 -> 7.9433e-05 | H10: =$B$9 -> 7.9433e-05 | I10: =$B$9 -> 7.9433e-05 | J10: =$B$9 -> 7.9433e-05 | ... Z10: =$B$9 -> 7.9433e-05
C11: =$B$9 -> 7.9433e-05 | D11: =$B$9 -> 7.9433e-05 | E11: =$B$9 -> 7.9433e-05 | F11: =$B$9 -> 7.9433e-05 | G11: =$B$9 -> 7.9433e-05 | H11: =$B$9 -> 7.9433e-05 | I11: =$B$9 -> 7.9433e-05 | J11: =$B$9 -> 7.9433e-05 | ... Z11: =$B$9 -> 7.9433e-05
C12: =$B$9 -> 7.9433e-05 | D12: =$B$9 -> 7.9433e-05 | E12: =$B$9 -> 7.9433e-05 | F12: =$B$9 -> 7.9433e-05 | G12: =$B$9 -> 7.9433e-05 | H12: =$B$9 -> 7.9433e-05 | I12: =$B$9 -> 7.9433e-05 | J12: =$B$9 -> 7.9433e-05 | ... Z12: =$B$9 -> 7.9433e-05
C13: =$B$9 -> 7.9433e-05 | D13: =$B$9 -> 7.9433e-05 | E13: =$B$9 -> 7.9433e-05 | F13: =$B$9 -> 7.9433e-05 | G13: =$B$9 -> 7.9433e-05 | H13: =$B$9 -> 7.9433e-05 | I13: =$B$9 -> 7.9433e-05 | J13: =$B$9 -> 7.9433e-05 | ... Z13: =$B$9 -> 7.9433e-05
C14: =$B$9 -> 7.9433e-05 | D14: =$B$9 -> 7.9433e-05 | E14: =$B$9 -> 7.9433e-05 | F14: =$B$9 -> 7.9433e-05 | G14: =$B$9 -> 7.9433e-05 | H14: =$B$9 -> 7.9433e-05 | I14: =$B$9 -> 7.9433e-05 | J14: =$B$9 -> 7.9433e-05 | ... Z14: =$B$9 -> 7.9433e-05
C15: =$B$9 -> 7.9433e-05 | D15: =$B$9 -> 7.9433e-05 | E15: =$B$9 -> 7.9433e-05 | F15: =$B$9 -> 7.9433e-05 | G15: =$B$9 -> 7.9433e-05 | H15: =$B$9 -> 7.9433e-05 | I15: =$B$9 -> 7.9433e-05 | J15: =$B$9 -> 7.9433e-05 | ... Z15: =$B$9 -> 7.9433e-05
C16: =$B$9 -> 7.9433e-05 | D16: =$B$9 -> 7.9433e-05 | E16: =$B$9 -> 7.9433e-05 | F16: =$B$9 -> 7.9433e-05 | G16: =$B$9 -> 7.9433e-05 | H16: =$B$9 -> 7.9433e-05 | I16: =$B$9 -> 7.9433e-05 | J16: =$B$9 -> 7.9433e-05 | ... Z16: =$B$9 -> 7.9433e-05
C17: =$B$9 -> 7.9433e-05 | D17: =$B$9 -> 7.9433e-05 | E17: =$B$9 -> 7.9433e-05 | F17: =$B$9 -> 7.9433e-05 | G17: =$B$9 -> 7.9433e-05 | H17: =$B$9 -> 7.9433e-05 | I17: =$B$9 -> 7.9433e-05 | J17: =$B$9 -> 7.9433e-05 | ... Z17: =$B$9 -> 7.9433e-05
C18: =$B$9 -> 7.9433e-05 | D18: =$B$9 -> 7.9433e-05 | E18: =$B$9 -> 7.9433e-05 | F18: =$B$9 -> 7.9433e-05 | G18: =$B$9 -> 7.9433e-05 | H18: =$B$9 -> 7.9433e-05 | I18: =$B$9 -> 7.9433e-05 | J18: =$B$9 -> 7.9433e-05 | ... Z18: =$B$9 -> 7.9433e-05
C19: =$B$9 -> 7.9433e-05 | D19: =$B$9 -> 7.9433e-05 | E19: =$B$9 -> 7.9433e-05 | F19: =$B$9 -> 7.9433e-05 | G19: =$B$9 -> 7.9433e-05 | H19: =$B$9 -> 7.9433e-05 | I19: =$B$9 -> 7.9433e-05 | J19: =$B$9 -> 7.9433e-05 | ... Z19: =$B$9 -> 7.9433e-05
C20: =$B$9 -> 7.9433e-05 | D20: =$B$9 -> 7.9433e-05 | E20: =$B$9 -> 7.9433e-05 | F20: =$B$9 -> 7.9433e-05 | G20: =$B$9 -> 7.9433e-05 | H20: =$B$9 -> 7.9433e-05 | I20: =$B$9 -> 7.9433e-05 | J20: =$B$9 -> 7.9433e-05 | ... Z20: =$B$9 -> 7.9433e-05
C21: =$B$9 -> 7.9433e-05 | D21: =$B$9 -> 7.9433e-05 | E21: =$B$9 -> 7.9433e-05 | F21: =$B$9 -> 7.9433e-05 | G21: =$B$9 -> 7.9433e-05 | H21: =$B$9 -> 7.9433e-05 | I21: =$B$9 -> 7.9433e-05 | J21: =$B$9 -> 7.9433e-05 | ... Z21: =$B$9 -> 7.9433e-05
... C63: =$B$9 -> 7.9433e-05 | D63: =$B$9 -> 7.9433e-05 | E63: =$B$9 -> 7.9433e-05 | F63: =$B$9 -> 7.9433e-05 | G63: =$B$9 -> 7.9433e-05 | H63: =$B$9 -> 7.9433e-05 | I63: =$B$9 -> 7.9433e-05 | J63: =$B$9 -> 7.9433e-05 | ... Z63: =$B$9 -> 7.9433e-05
C64: =10000*$B$9 -> 0.79433 | D64: =10000*$B$9 -> 0.79433 | E64: =10000*$B$9 -> 0.79433 | F64: =10000*$B$9 -> 0.79433 | G64: =10000*$B$9 -> 0.79433 | H64: =10000*$B$9 -> 0.79433 | I64: =10000*$B$9 -> 0.79433 | J64: =10000*$B$9 -> 0.79433 | ... Z64: =10000*$B$9 -> 0.79433

Sheet DEM
B2: Surface Elevation [m]
B3: Instructions: | C3: Paste the DEM data where y is the vertical axis in x is the horizontal axis
C4: x[cells]
B5: y [cells] | C5: 9.9598904 | D5: 9.9500866 | E5: 9.9408426 | F5: 9.9387627 | G5: 9.9397135 | H5: 9.939539 | I5: 9.9397774 | J5: 9.9394617 | K5: 9.9396334 | L5: 9.9393454 | M5: 9.9395313 | N5: 9.9393101 | O5: 9.9395266 | P5: 9.9393301 | Q5: 9.9396009 | R5: 9.9394302 | S5: 9.9397097 | T5: 9.9395628 | U5: 9.9397345 | V5: 9.9393969 | W5: 9.938961 | X5: 9.9403219 | Y5: 9.9514799 | Z5: 9.9590034
C6: 9.8861418 | D6: 9.8542109 | E6: 9.8333387 | F6: 9.832221 | G6: 9.8333054 | H6: 9.833602 | I6: 9.8334045 | J6: 9.8335495 | K6: 9.8332882 | L6: 9.8334265 | M6: 9.833231 | N6: 9.8333874 | O6: 9.8332338 | P6: 9.833396 | Q6: 9.8332901 | R6: 9.8334713 | S6: 9.8333979 | T6: 9.83358 | U6: 9.8333445 | V6: 9.8333206 | W6: 9.8323393 | X6: 9.83319 | Y6: 9.8569069 | Z6: 9.8919258
C7: 9.7896004 | D7: 9.7517948 | E7: 9.726305 | F7: 9.7232227 | G7: 9.7246275 | H7: 9.7252798 | I7: 9.7253647 | J7: 9.7255125 | K7: 9.7254047 | L7: 9.7255011 | M7: 9.7254057 | N7: 9.7254972 | O7: 9.7254057 | P7: 9.7254953 | Q7: 9.7253933 | R7: 9.7254782 | S7: 9.7253914 | T7: 9.7253933 | U7: 9.724966 | V7: 9.7247219 | W7: 9.7247772 | X7: 9.7296305 | Y7: 9.7588797 | Z7: 9.7985353
C8: 9.6842222 | D8: 9.6455297 | E8: 9.6188688 | F8: 9.616868 | G8: 9.6183977 | H8: 9.6187649 | I8: 9.619092 | J8: 9.6191425 | K8: 9.6191359 | L8: 9.6191568 | M8: 9.6191416 | N8: 9.6191616 | O8: 9.6191416 | P8: 9.6191587 | Q8: 9.6191244 | R8: 9.619133 | S8: 9.6190891 | T8: 9.6190357 | U8: 9.618494 | V8: 9.6182117 | W8: 9.6204338 | X8: 9.6284561 | Y8: 9.6573915 | Z8: 9.6965752
C9: 9.5843859 | D9: 9.5461702 | E9: 9.5186787 | F9: 9.51262 | G9: 9.5121107 | H9: 9.5123587 | I9: 9.5129137 | J9: 9.5130711 | K9: 9.5131063 | L9: 9.5131264 | M9: 9.5131359 | N9: 9.5131454 | O9: 9.513134 | P9: 9.513133 | Q9: 9.5130835 | R9: 9.5130739 | S9: 9.513011 | T9: 9.5128508 | U9: 9.5120935 | V9: 9.5122843 | W9: 9.5178881 | X9: 9.5318813 | Y9: 9.5623236 | Z9: 9.5992699
C10: 9.4918337 | D10: 9.452652 | E10: 9.4223967 | F10: 9.4103479 | G10: 9.4060202 | H10: 9.4061069 | I10: 9.4070473 | J10: 9.4071445 | K10: 9.4072304 | L10: 9.407238 | M10: 9.4072552 | N10: 9.407258 | O10: 9.4072533 | P10: 9.4072456 | Q10: 9.4072208 | R10: 9.407197 | S10: 9.4071312 | T10: 9.4071302 | U10: 9.4062529 | V10: 9.4060545 | W10: 9.4158306 | X10: 9.4387159 | Y10: 9.4725037 | Z10: 9.507988
C11: 9.4017544 | D11: 9.3627501 | E11: 9.329052 | F11: 9.3095675 | G11: 9.3004599 | H11: 9.2995749 | I11: 9.3007469 | J11: 9.301096 | K11: 9.3013163 | L11: 9.3013372 | M11: 9.3013906 | N11: 9.3013783 | O11: 9.3013763 | P11: 9.3014059 | Q11: 9.3013906 | R11: 9.3013992 | S11: 9.3011942 | T11: 9.3010254 | U11: 9.3004122 | V11: 9.3020449 | W11: 9.3165655 | X11: 9.3460445 | Y11: 9.383358 | Z11: 9.4184513
C12: 9.314374 | D12: 9.2749062 | E12: 9.2373524 | F12: 9.2089224 | G12: 9.1941109 | H12: 9.1934786 | I12: 9.1948881 | J12: 9.1951218 | K12: 9.1954269 | L12: 9.1954498 | M12: 9.1954889 | N12: 9.195487 | O12: 9.1955147 | P12: 9.1955843 | Q12: 9.1956568 | R12: 9.1957645 | S12: 9.1954784 | T12: 9.1952915 | U12: 9.1957417 | V12: 9.1987906 | W12: 9.2176991 | X12: 9.2546635 | Y12: 9.2954674 | Z12: 9.3311577
C13: 9.2263479 | D13: 9.1868649 | E13: 9.1462708 | F13: 9.1121788 | G13: 9.0924006 | H13: 9.0884066 | I13: 9.0886498 | J13: 9.0889511 | K13: 9.0894651 | L13: 9.0895767 | M13: 9.0896368 | N13: 9.0896721 | O13: 9.0897532 | P13: 9.0898819 | Q13: 9.089982 | R13: 9.0900316 | S13: 9.0894794 | T13: 9.0895576 | U13: 9.0927811 | V13: 9.1018429 | W13: 9.1259174 | X13: 9.1651382 | Y13: 9.2071867 | Z13: 9.2428179
C14: 9.1388025 | D14: 9.0991154 | E14: 9.0566063 | F14: 9.0174532 | G14: 8.9924583 | H14: 8.9848204 | I14: 8.982707 | J14: 8.9828777 | K14: 8.9836817 | L14: 8.9837751 | M14: 8.9838676 | N14: 8.9839563 | O14: 8.9840908 | P14: 8.9843025 | Q14: 8.984437 | R14: 8.98454 | S14: 8.9836416 | T14: 8.9833603 | U14: 8.9905682 | V14: 9.00842 | W14: 9.0378733 | X14: 9.0773067 | Y14: 9.1192303 | Z14: 9.1553593
C15: 9.0505447 | D15: 9.0110464 | E15: 8.9678841 | F15: 8.9271135 | G15: 8.8977537 | H15: 8.8832369 | I15: 8.8771238 | J15: 8.876605 | K15: 8.8777447 | L15: 8.8781157 | M15: 8.8783493 | N15: 8.8785229 | O15: 8.8786974 | P15: 8.878912 | Q15: 8.8789225 | R15: 8.8787565 | S15: 8.8774109 | T15: 8.8778648 | U15: 8.8895922 | V15: 8.9151211 | W15: 8.9496298 | X15: 8.9897947 | Y15: 9.0312643 | Z15: 9.0666685
C16: 8.9627285 | D16: 8.9230051 | E16: 8.8800821 | F16: 8.8394289 | G16: 8.805891 | H16: 8.7822781 | I16: 8.77069 | J16: 8.7703123 | K16: 8.7720709 | L16: 8.7724953 | M16: 8.7728939 | N16: 8.7731953 | O16: 8.7733517 | P16: 8.7735987 | Q16: 8.7733955 | R16: 8.7733078 | S16: 8.7718115 | T16: 8.7717381 | U16: 8.7879429 | V16: 8.8228626 | W16: 8.8619375 | X16: 8.9020443 | Y16: 8.94312 | Z16: 8.9791565
C17: 8.8743925 | D17: 8.8350286 | E17: 8.7924986 | F17: 8.7514334 | G17: 8.7140121 | H17: 8.6829977 | I17: 8.6656809 | J17: 8.6638203 | K17: 8.6656895 | L17: 8.6666899 | M17: 8.6675768 | N17: 8.6680012 | O17: 8.6682138 | P17: 8.6682768 | Q17: 8.6676779 | R17: 8.6670427 | S17: 8.6664543 | T17: 8.6710911 | U17: 8.6941299 | V17: 8.7326651 | W17: 8.7736797 | X17: 8.8142614 | Y17: 8.8550663 | Z17: 8.8905382
... C64: 4.7328038 | D64: 4.6925979 | E64: 4.6526709 | F64: 4.6127882 | G64: 4.5753951 | H64: 4.5352535 | I64: 4.4676485 | J64: 4.3674431 | K64: 4.2571311 | L64: 4.1501923 | M64: 4.0642524 | N64: 4.0149302 | O64: 4.0282145 | P64: 4.1065688 | Q64: 4.2085872 | R64: 4.3150754 | S64: 4.4133644 | T64: 4.4948215 | U64: 4.5556426 | V64: 4.5968051 | W64: 4.6344466 | X64: 4.6740918 | Y64: 4.7137718 | Z64: 4.7512612

Sheet Soil_Depth
B2: Soil Depth [m]
B3: Instructions: | C3: Paste the DEM data where y is the vertical axis en x is the horizontal axis
C4: x[cells]
B5: y [cells] | C5: 1 | D5: 1 | E5: 1 | F5: 1 | G5: 1 | H5: 1 | I5: 1 | J5: 1 | K5: 1 | L5: 1 | M5: 1 | N5: 1 | O5: 1 | P5: 1 | Q5: 1 | R5: 1 | S5: 1 | T5: 1 | U5: 1 | V5: 1 | W5: 1 | X5: 1 | Y5: 1 | Z5: 1
C6: 1 | D6: 1 | E6: 1 | F6: 1 | G6: 1 | H6: 1 | I6: 1 | J6: 1 | K6: 1 | L6: 1 | M6: 1 | N6: 1 | O6: 1 | P6: 1 | Q6: 1 | R6: 1 | S6: 1 | T6: 1 | U6: 1 | V6: 1 | W6: 1 | X6: 1 | Y6: 1 | Z6: 1
C7: 1 | D7: 1 | E7: 1 | F7: 1 | G7: 1 | H7: 1 | I7: 1 | J7: 1 | K7: 1 | L7: 1 | M7: 1 | N7: 1 | O7: 1 | P7: 1 | Q7: 1 | R7: 1 | S7: 1 | T7: 1 | U7: 1 | V7: 1 | W7: 1 | X7: 1 | Y7: 1 | Z7: 1
C8: 1 | D8: 1 | E8: 1 | F8: 1 | G8: 1 | H8: 1 | I8: 1 | J8: 1 | K8: 1 | L8: 1 | M8: 1 | N8: 1 | O8: 1 | P8: 1 | Q8: 1 | R8: 1 | S8: 1 | T8: 1 | U8: 1 | V8: 1 | W8: 1 | X8: 1 | Y8: 1 | Z8: 1
C9: 1 | D9: 1 | E9: 1 | F9: 1 | G9: 1 | H9: 1 | I9: 1 | J9: 1 | K9: 1 | L9: 1 | M9: 1 | N9: 1 | O9: 1 | P9: 1 | Q9: 1 | R9: 1 | S9: 1 | T9: 1 | U9: 1 | V9: 1 | W9: 1 | X9: 1 | Y9: 1 | Z9: 1
C10: 1 | D10: 1 | E10: 1 | F10: 1 | G10: 1 | H10: 1 | I10: 1 | J10: 1 | K10: 1 | L10: 1 | M10: 1 | N10: 1 | O10: 1 | P10: 1 | Q10: 1 | R10: 1 | S10: 1 | T10: 1 | U10: 1 | V10: 1 | W10: 1 | X10: 1 | Y10: 1 | Z10: 1
C11: 1 | D11: 1 | E11: 1 | F11: 1 | G11: 1 | H11: 1 | I11: 1 | J11: 1 | K11: 1 | L11: 1 | M11: 1 | N11: 1 | O11: 1 | P11: 1 | Q11: 1 | R11: 1 | S11: 1 | T11: 1 | U11: 1 | V11: 1 | W11: 1 | X11: 1 | Y11: 1 | Z11: 1
C12: 1 | D12: 1 | E12: 1 | F12: 1 | G12: 1 | H12: 1 | I12: 1 | J12: 1 | K12: 1 | L12: 1 | M12: 1 | N12: 1 | O12: 1 | P12: 1 | Q12: 1 | R12: 1 | S12: 1 | T12: 1 | U12: 1 | V12: 1 | W12: 1 | X12: 1 | Y12: 1 | Z12: 1
C13: 1 | D13: 1 | E13: 1 | F13: 1 | G13: 1 | H13: 1 | I13: 1 | J13: 1 | K13: 1 | L13: 1 | M13: 1 | N13: 1 | O13: 1 | P13: 1 | Q13: 1 | R13: 1 | S13: 1 | T13: 1 | U13: 1 | V13: 1 | W13: 1 | X13: 1 | Y13: 1 | Z13: 1
C14: 1 | D14: 1 | E14: 1 | F14: 1 | G14: 1 | H14: 1 | I14: 1 | J14: 1 | K14: 1 | L14: 1 | M14: 1 | N14: 1 | O14: 1 | P14: 1 | Q14: 1 | R14: 1 | S14: 1 | T14: 1 | U14: 1 | V14: 1 | W14: 1 | X14: 1 | Y14: 1 | Z14: 1
C15: 1 | D15: 1 | E15: 1 | F15: 1 | G15: 1 | H15: 1 | I15: 1 | J15: 1 | K15: 1 | L15: 1 | M15: 1 | N15: 1 | O15: 1 | P15: 1 | Q15: 1 | R15: 1 | S15: 1 | T15: 1 | U15: 1 | V15: 1 | W15: 1 | X15: 1 | Y15: 1 | Z15: 1
C16: 1 | D16: 1 | E16: 1 | F16: 1 | G16: 1 | H16: 1 | I16: 1 | J16: 1 | K16: 1 | L16: 1 | M16: 1 | N16: 1 | O16: 1 | P16: 1 | Q16: 1 | R16: 1 | S16: 1 | T16: 1 | U16: 1 | V16: 1 | W16: 1 | X16: 1 | Y16: 1 | Z16: 1
C17: 1 | D17: 1 | E17: 1 | F17: 1 | G17: 1 | H17: 1 | I17: 1 | J17: 1 | K17: 1 | L17: 1 | M17: 1 | N17: 1 | O17: 1 | P17: 1 | Q17: 1 | R17: 1 | S17: 1 | T17: 1 | U17: 1 | V17: 1 | W17: 1 | X17: 1 | Y17: 1 | Z17: 1
... C64: 1 | D64: 1 | E64: 1 | F64: 1 | G64: 1 | H64: 1 | I64: 1 | J64: 1 | K64: 1 | L64: 1 | M64: 1 | N64: 1 | O64: 1 | P64: 1 | Q64: 1 | R64: 1 | S64: 1 | T64: 1 | U64: 1 | V64: 1 | W64: 1 | X64: 1 | Y64: 1 | Z64: 1

Sheet Inflow_BC
B2: Hydrologic Input
B3: Time (min) | C3: Recharge rate [mm/h] | D3: ETP (mm/h)
B4: 0 | C4: 11.658254 | D4: 0
B5: 60 | C5: 11.236072 | D5: 0
B6: 120 | C6: 10.80854 | D6: 0
B7: 180 | C7: 1.6782785 | D7: 0
B8: 240 | C8: 0 | D8: 0
B9: 300 | C9: 0 | D9: 0
B10: 360 | C10: 0 | D10: 0
B11: 420 | C11: 0 | D11: 0
B12: 480 | C12: 0 | D12: 0
B13: 540 | C13: 0 | D13: 0
B14: 600 | C14: 11.351774 | D14: 0
B15: 660 | C15: 11.470961 | D15: 0
... B651: 38820 | C651: 0 | D651: 0

Sheet Assimilation_Data
B2: Particle Filter Inputs | K2: 1 | N2: 2 | Q2: 3 | T2: 4 | W2: 5 | Z2: 6 | AC2: 7 | AF2: 8 | AI2: 9 | AL2: 10 | AO2: 11 | AR2: 12 | AU2: 13 | AX2: 14 | BA2: 15
I3: Seepage Discharge | K3: LEO-C_1_0_0_CS451 | N3: LEO-C_3_0_0_CS451 | Q3: LEO-C_3_1.5_0_CS451 | T3: LEO-C_3_-1.5_0_CS451 | W3: LEO-C_3_3.5_0_CS451 | Z3: LEO-C_3_-3.5_0_CS451 | AC3: LEO-C_7_0_0_CS451 | AF3: LEO-C_7_1.5_0_CS451 | AI3: LEO-C_7_-1.5_0_CS451 | AL3: LEO-C_13_0_0_CS451 | AO3: LEO-C_13_1.5_0_CS451
B4: Particle Filter Seed Parameters | I4: Dishcarge Gauge | K4: GW Table Gauge | N4: GW Table Gauge | Q4: GW Table Gauge | T4: GW Table Gauge | W4: GW Table Gauge | Z4: GW Table Gauge | AC4: GW Table Gauge | AF4: GW Table Gauge | AI4: GW Table Gauge | AL4: GW Table Gauge | AO4: GW Table Gauge
B5: Parameter | C5: Initial Ensemble | D5: Parameter Std. | E5: Seed Value | F5: Min Val | G5: Max Val | I5: Time [min] | J5: Discharge [mm/h] | K5: GW Depth [m] | L5: x [m] | M5: y [m] | N5: GW Depth [m] | O5: x [m] | P5: y [m] | Q5: GW Depth [m] | R5: x [m] | S5: y [m] | T5: GW Depth [m] | U5: x [m] | V5: y [m] | W5: GW Depth [m] | X5: x [m] | Y5: y [m] | Z5: GW Depth [m] | AA5: x [m] | AB5: y [m] | AC5: GW Depth [m] | AD5: x [m] | AE5: y [m] | AF5: GW Depth [m] | AG5: x [m] | AH5: y [m] | AI5: GW Depth [m] | AJ5: x [m] | AK5: y [m] | AL5: GW Depth [m] | AM5: x [m] | AN5: y [m] | AO5: GW Depth [m] | AP5: x [m] | AQ5: y [m] | AR5: GW Depth [m] | AS5: x [m] | AT5: y [m] | AU5: GW Depth [m] | AV5: x [m] | AW5: y [m] | AX5: GW Depth [m] | AY5: x [m] | AZ5: y [m] | BA5: GW Depth [m] | BB5: x [m] | BC5: y [m]
B6: Ksat [m/s] | C6: =5*10^(-5) -> 5e-05 | D6: =5*10^-6 -> 5e-06 | E6: =GW_Ksat!C5 -> 7.9433e-05 | F6: =0.0000001 -> 1e-07 | G6: =0.01 -> 0.01 | I6: 0 | J6: 0.57413218 | K6: 0.4 | L6: 5.75 | M6: 3.2142857 | N6: 0.48 | O6: 5.75 | P6: 5.3571429 | Q6: 0.24 | R6: 7.8409091 | S6: 5.3571429 | T6: 0.23 | U6: 3.6590909 | V6: 5.3571429 | W6: 0.01 | X6: 9.9318182 | Y6: 5.3571429 | Z6: 0.01 | AA6: 3.6590909 | AB6: 5.3571429 | AC6: 0.37 | AD6: 5.75 | AE6: 9.6428571 | AF6: 0.14 | AG6: 7.8409091 | AH6: 9.6428571 | AI6: 0.12 | AJ6: 3.6590909 | AK6: 9.6428571 | AL6: 0.24 | AM6: 5.75 | AN6: 16.071429 | AO6: 0 | AP6: 7.8409091 | AQ6: 16.071429 | AR6: 0 | AS6: 3.6590909 | AT6: 16.071429 | AU6: 0.02 | AV6: 5.75 | AW6: 20.357143 | AX6: 0.01 | AY6: 7.8409091 | AZ6: 24.642857 | BA6: 0.01 | BB6: 3.6590909 | BC6: 24.642857
B7: n [-] | C7: =10*10^(-2) -> 0.1 | D7: =40*10^(-2) -> 0.4 | E7: =Input_Data!F12 -> 1.76 | F7: 1 | G7: 10 | I7: 60 | J7: 0.60459076 | K7: 0.405 | N7: 0.495 | Q7: 0.25 | T7: 0.245 | W7: 0.01 | Z7: 0.01 | AC7: 0.375 | AF7: 0.15 | AI7: 0.125 | AL7: 0.245 | AO7: 0 | AR7: 0 | AU7: 0.02 | AX7: 0.01 | BA7: 0.01
B8: porosity [-] | C8: 0 | D8: 0 | E8: =Input_Data!F13 -> 0.385 | F8: =0.385 -> 0.385 | G8: =0.385 -> 0.385 | I8: 120 | J8: 0.67896854 | K8: 0.41 | N8: 0.505 | Q8: 0.26 | T8: 0.255 | W8: 0.01 | Z8: 0.01 | AC8: 0.395 | AF8: 0.165 | AI8: 0.135 | AL8: 0.255 | AO8: 0.005 | AR8: 0.005 | AU8: 0.025 | AX8: 0.01 | BA8: 0.01
B9: alpha [1/m] | C9: =20*10^(-2) -> 0.2 | D9: =30*10^(-2) -> 0.3 | E9: =Input_Data!F14 -> -2.33 | F9: =-5 -> -5 | G9: -1 | I9: 180 | J9: 0.75881643 | K9: 0.415 | N9: 0.525 | Q9: 0.275 | T9: 0.275 | W9: 0.01 | Z9: 0.01 | AC9: 0.405 | AF9: 0.175 | AI9: 0.155 | AL9: 0.265 | AO9: 0.015 | AR9: 0.02 | AU9: 0.035 | AX9: 0.01 | BA9: 0.01
B10: irr_damping [-] | C10: =1*10^(-1) -> 0.1 | D10: =1*10^(-3) -> 0.001 | E10: =Input_Data!F17 -> 0.9 | F10: =0.8 -> 0.8 | G10: 1 | I10: 240 | J10: 0.78235705 | K10: 0.42 | N10: 0.54 | Q10: 0.295 | T10: 0.285 | W10: 0.01 | Z10: 0.01 | AC10: 0.43 | AF10: 0.195 | AI10: 0.175 | AL10: 0.285 | AO10: 0.03 | AR10: 0.035 | AU10: 0.045 | AX10: 0.01 | BA10: 0.01
B11: k [1/sec] | C11: =1*10^(-5) -> 1e-05 | D11: =1*10^(-6) -> 1e-06 | E11: =Input_Data!F15 -> 5e-05 | F11: =0.0000001 -> 1e-07 | G11: =0.01 -> 0.01 | I11: 300 | J11: 0.78193505 | K11: 0.43 | N11: 0.55 | Q11: 0.305 | T11: 0.305 | W11: 0.01 | Z11: 0.01 | AC11: 0.45 | AF11: 0.215 | AI11: 0.195 | AL11: 0.305 | AO11: 0.045 | AR11: 0.055 | AU11: 0.065 | AX11: 0.01 | BA11: 0.01
F12: =F11*10^6 -> 0.1 | G12: =G11*10^6 -> 10000 | I12: 360 | J12: 0.77513203 | K12: 0.43 | N12: 0.55 | Q12: 0.31 | T12: 0.31 | W12: 0.01 | Z12: 0.01 | AC12: 0.46 | AF12: 0.235 | AI12: 0.205 | AL12: 0.325 | AO12: 0.065 | AR12: 0.075 | AU12: 0.09 | AX12: 0.01 | BA12: 0.01
B13: Particle Filter Parameters | I13: 420 | J13: 0.76615506 | K13: 0.43 | N13: 0.55 | Q13: 0.31 | T13: 0.31 | W13: 0.01 | Z13: 0.01 | AC13: 0.46 | AF13: 0.24 | AI13: 0.21 | AL13: 0.335 | AO13: 0.08 | AR13: 0.09 | AU13: 0.11 | AX13: 0.01 | BA13: 0.01
I14: 480 | J14: 0.75643203 | K14: 0.42 | N14: 0.55 | Q14: 0.31 | T14: 0.305 | W14: 0.01 | Z14: 0.01 | AC14: 0.46 | AF14: 0.24 | AI14: 0.21 | AL14: 0.34 | AO14: 0.09 | AR14: 0.1 | AU14: 0.125 | AX14: 0.01 | BA14: 0.01
B15: N | C15: 400 | D15: particles | I15: 540 | J15: 0.7457684 | K15: 0.42 | N15: 0.55 | Q15: 0.31 | T15: 0.3 | W15: 0.01 | Z15: 0.01 | AC15: 0.46 | AF15: 0.24 | AI15: 0.21 | AL15: 0.345 | AO15: 0.095 | AR15: 0.105 | AU15: 0.13 | AX15: 0.01 | BA15: 0.01
I16: 600 | J16: 0.74192314 | K16: 0.425 | N16: 0.55 | Q16: 0.31 | T16: 0.305 | W16: 0.01 | Z16: 0.01 | AC16: 0.46 | AF16: 0.24 | AI16: 0.215 | AL16: 0.35 | AO16: 0.1 | AR16: 0.11 | AU16: 0.14 | AX16: 0.01 | BA16: 0.01
B17: flag_discharge | C17: 1 | I17: 660 | J17: 0.79188132 | K17: 0.43 | N17: 0.565 | Q17: 0.32 | T17: 0.315 | W17: 0.01 | Z17: 0.01 | AC17: 0.475 | AF17: 0.255 | AI17: 0.225 | AL17: 0.365 | AO17: 0.115 | AR17: 0.125 | AU17: 0.155 | AX17: 0.01 | BA17: 0.01
I18: 720 | J18: 0.88600638 | K18: 0.44 | N18: 0.585 | Q18: 0.335 | T18: 0.335 | W18: 0.01 | Z18: 0.01 | AC18: 0.495 | AF18: 0.275 | AI18: 0.245 | AL18: 0.39 | AO18: 0.135 | AR18: 0.15 | AU18: 0.175 | AX18: 0.01 | BA18: 0.01
B19: Discharge Error Std. | C19: 0.05 | D19: mm/h | I19: 780 | J19: 0.99378015 | K19: 0.45 | N19: 0.605 | Q19: 0.36 | T19: 0.36 | W19: 0.01 | Z19: 0.01 | AC19: 0.525 | AF19: 0.295 | AI19: 0.27 | AL19: 0.42 | AO19: 0.165 | AR19: 0.18 | AU19: 0.205 | AX19: 0.01 | BA19: 0.01
I20: 840 | J20: 1.0350145 | K20: 0.46 | N20: 0.63 | Q20: 0.385 | T20: 0.385 | W20: 0.01 | Z20: 0.02 | AC20: 0.55 | AF20: 0.325 | AI20: 0.3 | AL20: 0.46 | AO20: 0.2 | AR20: 0.22 | AU20: 0.24 | AX20: 0.015 | BA20: 0.025
B21: GW Depth Error Std. | C21: 0.025 | D21: m | I21: 900 | J21: 1.0349582 | K21: 0.47 | N21: 0.645 | Q21: 0.405 | T21: 0.405 | W21: 0.01 | Z21: 0.035 | AC21: 0.575 | AF21: 0.355 | AI21: 0.33 | AL21: 0.495 | AO21: 0.235 | AR21: 0.26 | AU21: 0.28 | AX21: 0.025 | BA21: 0.045
I22: 960 | J22: 1.023638 | K22: 0.47 | N22: 0.66 | Q22: 0.425 | T22: 0.42 | W22: 0.015 | Z22: 0.045 | AC22: 0.595 | AF22: 0.375 | AI22: 0.355 | AL22: 0.525 | AO22: 0.27 | AR22: 0.295 | AU22: 0.315 | AX22: 0.045 | BA22: 0.065
B23: Gauges Used in the PF | I23: 1020 | J23: 1.007662 | K23: 0.475 | N23: 0.67 | Q23: 0.435 | T23: 0.43 | W23: 0.02 | Z23: 0.065 | AC23: 0.61 | AF23: 0.395 | AI23: 0.37 | AL23: 0.555 | AO23: 0.295 | AR23: 0.315 | AU23: 0.345 | AX23: 0.065 | BA23: 0.095
B24: Gauge ID | C24: Check | I24: 1080 | J24: 0.99335435 | K24: 0.48 | N24: 0.675 | Q24: 0.445 | T24: 0.44 | W24: 0.02 | Z24: 0.075 | AC24: 0.62 | AF24: 0.405 | AI24: 0.38 | AL24: 0.575 | AO24: 0.325 | AR24: 0.335 | AU24: 0.37 | AX24: 0.085 | BA24: 0.115
B25: 1 | C25: 0 | I25: 1140 | J25: 0.98036869 | K25: 0.48 | N25: 0.68 | Q25: 0.45 | T25: 0.44 | W25: 0.03 | Z25: 0.08 | AC25: 0.63 | AF25: 0.415 | AI25: 0.39 | AL25: 0.585 | AO25: 0.34 | AR25: 0.355 | AU25: 0.395 | AX25: 0.105 | BA25: 0.135
B26: 2 | C26: 1 | I26: 1200 | J26: 0.96869536 | K26: 0.48 | N26: 0.68 | Q26: 0.46 | T26: 0.45 | W26: 0.025 | Z26: 0.09 | AC26: 0.64 | AF26: 0.42 | AI26: 0.4 | AL26: 0.605 | AO26: 0.355 | AR26: 0.365 | AU26: 0.415 | AX26: 0.11 | BA26: 0.15
B27: 3 | C27: 0 | I27: 1260 | J27: 0.95466242 | K27: 0.48 | N27: 0.69 | Q27: 0.46 | T27: 0.45 | W27: 0.02 | Z27: 0.09 | AC27: 0.64 | AF27: 0.425 | AI27: 0.4 | AL27: 0.615 | AO27: 0.365 | AR27: 0.375 | AU27: 0.43 | AX27: 0.11 | BA27: 0.155
B28: 4 | C28: 0 | I28: 1320 | J28: 0.94343878 | K28: 0.48 | N28: 0.69 | Q28: 0.46 | T28: 0.45 | W28: 0.015 | Z28: 0.085 | AC28: 0.65 | AF28: 0.43 | AI28: 0.41 | AL28: 0.625 | AO28: 0.375 | AR28: 0.385 | AU28: 0.445 | AX28: 0.11 | BA28: 0.16
B29: 5 | C29: 0 | I29: 1380 | J29: 0.93275938 | K29: 0.48 | N29: 0.69 | Q29: 0.465 | T29: 0.45 | W29: 0.01 | Z29: 0.08 | AC29: 0.65 | AF29: 0.43 | AI29: 0.41 | AL29: 0.63 | AO29: 0.38 | AR29: 0.39 | AU29: 0.455 | AX29: 0.11 | BA29: 0.16
B30: 6 | C30: 0 | I30: 1440 | J30: 0.92405574 | K30: 0.485 | N30: 0.69 | Q30: 0.47 | T30: 0.46 | W30: 0.005 | Z30: 0.08 | AC30: 0.65 | AF30: 0.44 | AI30: 0.41 | AL30: 0.64 | AO30: 0.39 | AR30: 0.4 | AU30: 0.465 | AX30: 0.105 | BA30: 0.16
B31: 7 | C31: 1 | I31: 1500 | J31: 0.91368321 | K31: 0.49 | N31: 0.69 | Q31: 0.47 | T31: 0.46 | W31: 0 | Z31: 0.075 | AC31: 0.66 | AF31: 0.44 | AI31: 0.41 | AL31: 0.64 | AO31: 0.39 | AR31: 0.4 | AU31: 0.47 | AX31: 0.1 | BA31: 0.16
B32: 8 | C32: 0 | I32: 1560 | J32: 0.90534947 | K32: 0.49 | N32: 0.695 | Q32: 0.47 | T32: 0.46 | W32: 0 | Z32: 0.07 | AC32: 0.66 | AF32: 0.44 | AI32: 0.41 | AL32: 0.65 | AO32: 0.4 | AR32: 0.41 | AU32: 0.47 | AX32: 0.1 | BA32: 0.155
B33: 9 | C33: 0 | I33: 1620 | J33: 0.89520704 | K33: 0.49 | N33: 0.7 | Q33: 0.47 | T33: 0.46 | W33: 0 | Z33: 0.07 | AC33: 0.66 | AF33: 0.44 | AI33: 0.41 | AL33: 0.65 | AO33: 0.4 | AR33: 0.41 | AU33: 0.48 | AX33: 0.1 | BA33: 0.15
B34: 10 | C34: 1 | I34: 1680 | J34: 0.89088926 | K34: 0.49 | N34: 0.695 | Q34: 0.47 | T34: 0.46 | W34: 0 | Z34: 0.065 | AC34: 0.66 | AF34: 0.44 | AI34: 0.41 | AL34: 0.655 | AO34: 0.4 | AR34: 0.41 | AU34: 0.48 | AX34: 0.1 | BA34: 0.15
B35: 11 | C35: 0 | I35: 1740 | J35: 0.8809432 | K35: 0.49 | N35: 0.69 | Q35: 0.47 | T35: 0.455 | W35: 0 | Z35: 0.06 | AC35: 0.66 | AF35: 0.44 | AI35: 0.41 | AL35: 0.66 | AO35: 0.405 | AR35: 0.41 | AU35: 0.48 | AX35: 0.09 | BA35: 0.15
B36: 12 | C36: 0 | I36: 1800 | J36: 0.87624441 | K36: 0.49 | N36: 0.69 | Q36: 0.47 | T36: 0.45 | W36: 0 | Z36: 0.06 | AC36: 0.66 | AF36: 0.44 | AI36: 0.41 | AL36: 0.66 | AO36: 0.41 | AR36: 0.41 | AU36: 0.48 | AX36: 0.09 | BA36: 0.145
... B39: 15 | C39: 0 | I39: 1980 | J39: 0.85705955 | K39: 0.48 | N39: 0.69 | Q39: 0.46 | T39: 0.45 | W39: 0 | Z39: 0.04 | AC39: 0.66 | AF39: 0.44 | AI39: 0.41 | AL39: 0.66 | AO39: 0.41 | AR39: 0.41 | AU39: 0.47 | AX39: 0.055 | BA39: 0.12
I40: 2040 | J40: 0.85164925 | K40: 0.48 | N40: 0.69 | Q40: 0.46 | T40: 0.45 | W40: 0 | Z40: 0.035 | AC40: 0.655 | AF40: 0.44 | AI40: 0.405 | AL40: 0.655 | AO40: 0.4 | AR40: 0.41 | AU40: 0.47 | AX40: 0.04 | BA40: 0.11
I41: 2100 | J41: 0.84633934 | K41: 0.48 | N41: 0.685 | Q41: 0.46 | T41: 0.445 | W41: 0 | Z41: 0.03 | AC41: 0.65 | AF41: 0.435 | AI41: 0.4 | AL41: 0.65 | AO41: 0.4 | AR41: 0.41 | AU41: 0.465 | AX41: 0.025 | BA41: 0.095
I42: 2160 | J42: 0.84058439 | K42: 0.48 | N42: 0.68 | Q42: 0.455 | T42: 0.44 | W42: 0 | Z42: 0.02 | AC42: 0.65 | AF42: 0.43 | AI42: 0.4 | AL42: 0.65 | AO42: 0.4 | AR42: 0.41 | AU42: 0.46 | AX42: 0.015 | BA42: 0.085
I43: 2220 | J43: 0.83637368 | K43: 0.48 | N43: 0.68 | Q43: 0.45 | T43: 0.44 | W43: 0 | Z43: 0.015 | AC43: 0.65 | AF43: 0.43 | AI43: 0.4 | AL43: 0.65 | AO43: 0.395 | AR43: 0.4 | AU43: 0.455 | AX43: 0.01 | BA43: 0.075
...
